<?xml version="1.0" encoding="UTF-8"?>
<sdf version='1.9'>
  <model name='xlab550'>
    <self_collide>false</self_collide>
    <static>false</static>

    <!-- base link -->
    <link name="base_link">
      <!-- visual -->
      <visual name="base_link_visual">
        <geometry>
          <mesh>
            <uri>meshes/base.stl</uri>
          </mesh>
        </geometry>
        <material>
          <script>
            <name>Gazebo/DarkGrey</name>
            <uri>file://media/materials/scripts/gazebo.material</uri>
          </script>
        </material>
      </visual>

      <!-- inertial -->
      <inertial>
        <mass>2.4</mass>
        <pose>0 0 -0.03241 0 0 0</pose>
        <inertia>
          <ixx>0.038307</ixx>
          <ixy>0</ixy>
          <ixz>0</ixz>
          <iyy>0.037836</iyy>
          <iyz>0</iyz>
          <izz>0.047572</izz>
        </inertia>
      </inertial>

      <!-- base link collisions -->
      <collision name="base_link_collision_0">
        <pose>0 0 -0.13935 0 0 0</pose>
        <geometry>
          <box>
            <size>0.351075 0.301075 0.2787</size>
          </box>
        </geometry>
      </collision>
      <collision name="base_link_collision_1">
        <pose>0 0 0.022 0 0 0</pose>
        <geometry>
          <box>
            <size>0.473 0.473 0.044</size>
          </box>
        </geometry>
      </collision>
      <collision name="base_link_collision_2">
        <pose>0 0 0.083 0 0 0</pose>
        <geometry>
          <box>
            <size>0.16 0.16 0.079</size>
          </box>
        </geometry>
      </collision>

      <!-- rotor collisions -->
      <collision name="rotor_collision_0">
        <pose>0.20186889868 -0.20186889868 0.03913573795 0 -0.05002085676041132 -0.7853981633974483</pose>
        <geometry>
          <cylinder>
            <length>0.065</length>
            <radius>0.1778</radius>
          </cylinder>
        </geometry>
      </collision>
      <collision name="rotor_collision_1">
        <pose>-0.20186889868 0.20186889868 0.03913573795 0 0.05002085676041132 -0.7853981633974483</pose>
        <geometry>
          <cylinder>
            <length>0.065</length>
            <radius>0.1778</radius>
          </cylinder>
        </geometry>
      </collision>
      <collision name="rotor_collision_2">
        <pose>0.20186889868 0.20186889868 0.03913573795 0 -0.05002085676041132 0.7853981633974483</pose>
        <geometry>
          <cylinder>
            <length>0.065</length>
            <radius>0.1778</radius>
          </cylinder>
        </geometry>
      </collision>
      <collision name="rotor_collision_3">
        <pose>-0.20186889868 -0.20186889868 0.03913573795 0 0.05002085676041132 0.7853981633974483</pose>
        <geometry>
          <cylinder>
            <length>0.065</length>
            <radius>0.1778</radius>
          </cylinder>
        </geometry>
      </collision>

      <!-- air pressure sensor -->
      <sensor name="air_pressure_sensor" type="air_pressure">
        <always_on>1</always_on>
        <update_rate>50</update_rate>
        <air_pressure>
          <pressure>
            <noise type="gaussian">
              <mean>0</mean>
              <stddev>0.01</stddev>
            </noise>
          </pressure>
        </air_pressure>
      </sensor>

      <!-- imu sensor -->
      <sensor name="imu_sensor" type="imu">
        <always_on>1</always_on>
        <update_rate>250</update_rate>
        <imu>
          <angular_velocity>
            <x>
              <noise type="gaussian">
                <mean>0</mean>
                <stddev>0.00018665</stddev>
                <dynamic_bias_stddev>3.8785e-05</dynamic_bias_stddev>
                <dynamic_bias_correlation_time>1000</dynamic_bias_correlation_time>
              </noise>
            </x>
            <y>
              <noise type="gaussian">
                <mean>0</mean>
                <stddev>0.00018665</stddev>
                <dynamic_bias_stddev>3.8785e-05</dynamic_bias_stddev>
                <dynamic_bias_correlation_time>1000</dynamic_bias_correlation_time>
              </noise>
            </y>
            <z>
              <noise type="gaussian">
                <mean>0</mean>
                <stddev>0.00018665</stddev>
                <dynamic_bias_stddev>3.8785e-05</dynamic_bias_stddev>
                <dynamic_bias_correlation_time>1000</dynamic_bias_correlation_time>
              </noise>
            </z>
          </angular_velocity>
          <linear_acceleration>
            <x>
              <noise type="gaussian">
                <mean>0</mean>
                <stddev>0.00186</stddev>
                <dynamic_bias_stddev>0.006</dynamic_bias_stddev>
                <dynamic_bias_correlation_time>300</dynamic_bias_correlation_time>
              </noise>
            </x>
            <y>
              <noise type="gaussian">
                <mean>0</mean>
                <stddev>0.00186</stddev>
                <dynamic_bias_stddev>0.006</dynamic_bias_stddev>
                <dynamic_bias_correlation_time>300</dynamic_bias_correlation_time>
              </noise>
            </y>
            <z>
              <noise type="gaussian">
                <mean>0</mean>
                <stddev>0.00186</stddev>
                <dynamic_bias_stddev>0.006</dynamic_bias_stddev>
                <dynamic_bias_correlation_time>300</dynamic_bias_correlation_time>
              </noise>
            </z>
          </linear_acceleration>
        </imu>
      </sensor>

      <!-- navsat sensor -->
      <sensor name="navsat_sensor" type="navsat">
        <always_on>1</always_on>
        <update_rate>30</update_rate>
      </sensor>

      <!-- camera sensors -->
      <sensor name="camera_down_left" type="camera">
        <pose>0 0.19625 0.0033 0 1.5707963267948966 1.5707963267948966</pose>
        <camera>
          <triggered>true</triggered>
          <trigger_topic>camera/trigger</trigger_topic>
          <horizontal_fov>1.3980584272883465</horizontal_fov>
          <image>
            <width>640</width>
            <height>400</height>
          </image>
          <clip>
            <near>0.05</near>
            <far>3000</far>
          </clip>
        </camera>
        <always_on>1</always_on>
        <update_rate>60</update_rate>
        <visualize>true</visualize>
        <topic>camera/img/down_left</topic>
      </sensor>
      <sensor name="camera_down_right" type="camera">
        <pose>0 -0.19625 0.0033 0 1.5707963267948966 -1.5707963267948966</pose>
        <camera>
          <triggered>true</triggered>
          <trigger_topic>camera/trigger</trigger_topic>
          <horizontal_fov>1.3980584272883465</horizontal_fov>
          <image>
            <width>640</width>
            <height>400</height>
          </image>
          <clip>
            <near>0.05</near>
            <far>3000</far>
          </clip>
        </camera>
        <always_on>1</always_on>
        <update_rate>60</update_rate>
        <visualize>true</visualize>
        <topic>camera/img/down_right</topic>
      </sensor>
      <sensor name="camera_front_left" type="camera">
        <pose>0.0565 0.05 -0.0252 0 0 0</pose>
        <camera>
          <triggered>true</triggered>
          <trigger_topic>camera/trigger</trigger_topic>
          <horizontal_fov>1.3980584272883465</horizontal_fov>
          <image>
            <width>640</width>
            <height>400</height>
          </image>
          <clip>
            <near>0.05</near>
            <far>3000</far>
          </clip>
        </camera>
        <always_on>1</always_on>
        <update_rate>60</update_rate>
        <visualize>true</visualize>
        <topic>camera/img/front_left</topic>
      </sensor>
      <sensor name="camera_front_right" type="camera">
        <pose>0.0565 -0.05 -0.0252 0 0 0</pose>
        <camera>
          <triggered>true</triggered>
          <trigger_topic>camera/trigger</trigger_topic>
          <horizontal_fov>1.3980584272883465</horizontal_fov>
          <image>
            <width>640</width>
            <height>400</height>
          </image>
          <clip>
            <near>0.05</near>
            <far>3000</far>
          </clip>
        </camera>
        <always_on>1</always_on>
        <update_rate>60</update_rate>
        <visualize>true</visualize>
        <topic>camera/img/front_right</topic>
      </sensor>
    </link>

    <!-- rotor link 0 -->
    <link name="rotor_link_0">
      <!-- pose -->
      <pose>0.20186889868 -0.20186889868 0.03913573795 0 -0.05002085676041132 -0.7853981633974483</pose>

      <!-- visual -->
      <visual name="rotor_link_0_visual">
        <geometry>
          <mesh>
            <uri>meshes/rotorccw.stl</uri>
          </mesh>
        </geometry>
        <material>
          <script>
            <name>Gazebo/Grey</name>
            <uri>file://media/materials/scripts/gazebo.material</uri>
          </script>
        </material>
      </visual>

      <!-- inertial -->
      <inertial>
        <pose>0 0 0.019621 0 0 0</pose>
        <mass>0.048829</mass>
        <inertia>
          <ixx>0.000095</ixx>
          <iyy>0.000008</iyy>
          <izz>0.000098</izz>
        </inertia>
      </inertial>
    </link>

    <!-- rotor link 1 -->
    <link name="rotor_link_1">
      <!-- pose -->
      <pose>-0.20186889868 0.20186889868 0.03913573795 0 -0.05002085676041132 2.356194490192345</pose>

      <!-- visual -->
      <visual name="rotor_link_1_visual">
        <geometry>
          <mesh>
            <uri>meshes/rotorccw.stl</uri>
          </mesh>
        </geometry>
        <material>
          <script>
            <name>Gazebo/Grey</name>
            <uri>file://media/materials/scripts/gazebo.material</uri>
          </script>
        </material>
      </visual>

      <!-- inertial -->
      <inertial>
        <pose>0 0 0.019621 0 0 0</pose>
        <mass>0.048829</mass>
        <inertia>
          <ixx>0.000095</ixx>
          <iyy>0.000008</iyy>
          <izz>0.000098</izz>
        </inertia>
      </inertial>
    </link>

    <!-- rotor link 2 -->
    <link name="rotor_link_2">
      <!-- pose -->
      <pose>0.20186889868 0.20186889868 0.03913573795 0 -0.05002085676041132 0.7853981633974483</pose>

      <!-- visual -->
      <visual name="rotor_link_2_visual">
        <geometry>
          <mesh>
            <uri>meshes/rotorcw.stl</uri>
          </mesh>
        </geometry>
        <material>
          <script>
            <name>Gazebo/Grey</name>
            <uri>file://media/materials/scripts/gazebo.material</uri>
          </script>
        </material>
      </visual>

      <!-- inertial -->
      <inertial>
        <pose>0 0 0.019621 0 0 0</pose>
        <mass>0.048829</mass>
        <inertia>
          <ixx>0.000095</ixx>
          <iyy>0.000008</iyy>
          <izz>0.000098</izz>
        </inertia>
      </inertial>
    </link>

    <!-- rotor link 3 -->
    <link name="rotor_link_3">
      <!-- pose -->
      <pose>-0.20186889868 -0.20186889868 0.03913573795 0 -0.05002085676041132 -2.356194490192345</pose>

      <!-- visual -->
      <visual name="rotor_link_3_visual">
        <geometry>
          <mesh>
            <uri>meshes/rotorcw.stl</uri>
          </mesh>
        </geometry>
        <material>
          <script>
            <name>Gazebo/Grey</name>
            <uri>file://media/materials/scripts/gazebo.material</uri>
          </script>
        </material>
      </visual>

      <!-- inertial -->
      <inertial>
        <pose>0 0 0.019621 0 0 0</pose>
        <mass>0.048829</mass>
        <inertia>
          <ixx>0.000095</ixx>
          <iyy>0.000008</iyy>
          <izz>0.000098</izz>
        </inertia>
      </inertial>
    </link>

    <!-- rotor joint 0 -->
    <joint name="rotor_joint_0" type="revolute">
      <parent>base_link</parent>
      <child>rotor_link_0</child>
      <axis>
        <xyz>0 0 1</xyz>
      </axis>
    </joint>

    <!-- rotor joint 1 -->
    <joint name="rotor_joint_1" type="revolute">
      <parent>base_link</parent>
      <child>rotor_link_1</child>
      <axis>
        <xyz>0 0 1</xyz>
      </axis>
    </joint>

    <!-- rotor joint 2 -->
    <joint name="rotor_joint_2" type="revolute">
      <parent>base_link</parent>
      <child>rotor_link_2</child>
      <axis>
        <xyz>0 0 1</xyz>
      </axis>
    </joint>

    <!-- rotor joint 3 -->
    <joint name="rotor_joint_3" type="revolute">
      <parent>base_link</parent>
      <child>rotor_link_3</child>
      <axis>
        <xyz>0 0 1</xyz>
      </axis>
    </joint>

    <!-- mc motor plugins -->
    <plugin filename="gz-sim-multicopter-motor-model-system" name="gz::sim::systems::MulticopterMotorModel">
      <jointName>rotor_joint_0</jointName>
      <linkName>rotor_link_0</linkName>
      <turningDirection>ccw</turningDirection>
      <timeConstantUp>0.0125</timeConstantUp>
      <timeConstantDown>0.025</timeConstantDown>
      <maxRotVelocity>1000.0</maxRotVelocity>
      <motorConstant>8.54858e-06</motorConstant>
      <momentConstant>0.016</momentConstant>
      <commandSubTopic>command/motor_speed</commandSubTopic>
      <motorNumber>0</motorNumber>
      <rotorDragCoefficient>8.06428e-05</rotorDragCoefficient>
      <rollingMomentCoefficient>1e-06</rollingMomentCoefficient>
      <rotorVelocitySlowdownSim>10</rotorVelocitySlowdownSim>
      <motorType>velocity</motorType>
    </plugin>
    <plugin filename="gz-sim-multicopter-motor-model-system" name="gz::sim::systems::MulticopterMotorModel">
      <jointName>rotor_joint_1</jointName>
      <linkName>rotor_link_1</linkName>
      <turningDirection>ccw</turningDirection>
      <timeConstantUp>0.0125</timeConstantUp>
      <timeConstantDown>0.025</timeConstantDown>
      <maxRotVelocity>1000.0</maxRotVelocity>
      <motorConstant>8.54858e-06</motorConstant>
      <momentConstant>0.016</momentConstant>
      <commandSubTopic>command/motor_speed</commandSubTopic>
      <motorNumber>1</motorNumber>
      <rotorDragCoefficient>8.06428e-05</rotorDragCoefficient>
      <rollingMomentCoefficient>1e-06</rollingMomentCoefficient>
      <rotorVelocitySlowdownSim>10</rotorVelocitySlowdownSim>
      <motorType>velocity</motorType>
    </plugin>
    <plugin filename="gz-sim-multicopter-motor-model-system" name="gz::sim::systems::MulticopterMotorModel">
      <jointName>rotor_joint_2</jointName>
      <linkName>rotor_link_2</linkName>
      <turningDirection>cw</turningDirection>
      <timeConstantUp>0.0125</timeConstantUp>
      <timeConstantDown>0.025</timeConstantDown>
      <maxRotVelocity>1000.0</maxRotVelocity>
      <motorConstant>8.54858e-06</motorConstant>
      <momentConstant>0.016</momentConstant>
      <commandSubTopic>command/motor_speed</commandSubTopic>
      <motorNumber>2</motorNumber>
      <rotorDragCoefficient>8.06428e-05</rotorDragCoefficient>
      <rollingMomentCoefficient>1e-06</rollingMomentCoefficient>
      <rotorVelocitySlowdownSim>10</rotorVelocitySlowdownSim>
      <motorType>velocity</motorType>
    </plugin>
    <plugin filename="gz-sim-multicopter-motor-model-system" name="gz::sim::systems::MulticopterMotorModel">
      <jointName>rotor_joint_3</jointName>
      <linkName>rotor_link_3</linkName>
      <turningDirection>cw</turningDirection>
      <timeConstantUp>0.0125</timeConstantUp>
      <timeConstantDown>0.025</timeConstantDown>
      <maxRotVelocity>1000.0</maxRotVelocity>
      <motorConstant>8.54858e-06</motorConstant>
      <momentConstant>0.016</momentConstant>
      <commandSubTopic>command/motor_speed</commandSubTopic>
      <motorNumber>3</motorNumber>
      <rotorDragCoefficient>8.06428e-05</rotorDragCoefficient>
      <rollingMomentCoefficient>1e-06</rollingMomentCoefficient>
      <rotorVelocitySlowdownSim>10</rotorVelocitySlowdownSim>
      <motorType>velocity</motorType>
    </plugin>
  </model>
</sdf>
